Traceback (most recent call last):
  File "/home/runner/.cache/pypoetry/virtualenvs/python_for_food_scientists-OgywevK--py3.9/lib/python3.9/site-packages/jupyter_cache/executors/utils.py", line 51, in single_nb_execution
    executenb(
  File "/home/runner/.cache/pypoetry/virtualenvs/python_for_food_scientists-OgywevK--py3.9/lib/python3.9/site-packages/nbclient/client.py", line 1204, in execute
    return NotebookClient(nb=nb, resources=resources, km=km, **kwargs).execute()
  File "/home/runner/.cache/pypoetry/virtualenvs/python_for_food_scientists-OgywevK--py3.9/lib/python3.9/site-packages/nbclient/util.py", line 84, in wrapped
    return just_run(coro(*args, **kwargs))
  File "/home/runner/.cache/pypoetry/virtualenvs/python_for_food_scientists-OgywevK--py3.9/lib/python3.9/site-packages/nbclient/util.py", line 62, in just_run
    return loop.run_until_complete(coro)
  File "/opt/hostedtoolcache/Python/3.9.21/x64/lib/python3.9/asyncio/base_events.py", line 647, in run_until_complete
    return future.result()
  File "/home/runner/.cache/pypoetry/virtualenvs/python_for_food_scientists-OgywevK--py3.9/lib/python3.9/site-packages/nbclient/client.py", line 663, in async_execute
    await self.async_execute_cell(
  File "/home/runner/.cache/pypoetry/virtualenvs/python_for_food_scientists-OgywevK--py3.9/lib/python3.9/site-packages/nbclient/client.py", line 965, in async_execute_cell
    await self._check_raise_for_error(cell, cell_index, exec_reply)
  File "/home/runner/.cache/pypoetry/virtualenvs/python_for_food_scientists-OgywevK--py3.9/lib/python3.9/site-packages/nbclient/client.py", line 862, in _check_raise_for_error
    raise CellExecutionError.from_cell_and_msg(cell, exec_reply_content)
nbclient.exceptions.CellExecutionError: An error occurred while executing the following cell:
------------------
print_value_of_x()
print('----------')
print_value_of_x_y_local()
print('----------')
print('Global value of x:', x, 'unchanged')
print('Value of y:', y)
------------------

[0;31m---------------------------------------------------------------------------[0m
[0;31mNameError[0m                                 Traceback (most recent call last)
Cell [0;32mIn[16], line 6[0m
[1;32m      4[0m [38;5;28mprint[39m([38;5;124m'[39m[38;5;124m----------[39m[38;5;124m'[39m)
[1;32m      5[0m [38;5;28mprint[39m([38;5;124m'[39m[38;5;124mGlobal value of x:[39m[38;5;124m'[39m, x, [38;5;124m'[39m[38;5;124munchanged[39m[38;5;124m'[39m)
[0;32m----> 6[0m [38;5;28mprint[39m([38;5;124m'[39m[38;5;124mValue of y:[39m[38;5;124m'[39m, [43my[49m)

[0;31mNameError[0m: name 'y' is not defined
NameError: name 'y' is not defined

